<?xml version="1.0"?>
<robot xmlns:xacro="http://www.ros.org/wiki/xacro">

  <!-- Macro: wheels + ros2_control -->
  <xacro:macro name="wheelchair_ros2_control"
               params="wheel_radius wheel_width wheel_separation wheel_x wheel_z">

    <!-- Half of wheel separation (base_link -> each wheel center) -->
    <xacro:property name="half_sep" value="${float(wheel_separation)/2.0}"/>



    <!-- Left wheel -->
    <link name="left_wheel_link">
      <visual>
        <origin xyz="0 0 0" rpy="${pi/2} 0 0"/>
        <geometry>
          <cylinder radius="${wheel_radius}" length="${wheel_width}"/>
        </geometry>
        <material name="black"/>
      </visual>
      <collision>
        <origin xyz="0 0 0" rpy="${pi/2} 0 0"/>
        <geometry>
          <cylinder radius="${wheel_radius}" length="${wheel_width}"/>
        </geometry>
      </collision>
    </link>

    <joint name="left_wheel_joint" type="continuous">
      <parent link="base_link"/>
      <child link="left_wheel_link"/>
      <origin xyz="${wheel_x} ${half_sep} ${wheel_z}" rpy="0 0 0"/>
      <axis xyz="0 1 0"/>
    </joint>



    <!-- Right wheel -->
    <link name="right_wheel_link">
      <visual>
        <origin xyz="0 0 0" rpy="${pi/2} 0 0"/>
        <geometry>
          <cylinder radius="${wheel_radius}" length="${wheel_width}"/>
        </geometry>
        <material name="black"/>
      </visual>
      <collision>
        <origin xyz="0 0 0" rpy="${pi/2} 0 0"/>
        <geometry>
          <cylinder radius="${wheel_radius}" length="${wheel_width}"/>
        </geometry>
      </collision>
    </link>

    <joint name="right_wheel_joint" type="continuous">
      <parent link="base_link"/>
      <child link="right_wheel_link"/>
      <origin xyz="${wheel_x} ${-half_sep} ${wheel_z}" rpy="0 0 0"/>
      <axis xyz="0 1 0"/>
    </joint>



    <!-- ros2_control block -->
    <ros2_control name="WheelchairSystem" type="system">
      <hardware>
        <plugin>wheelchair_hardware/WheelchairSystemHardware</plugin>
        <param name="serial_port">/dev/ttyUSB0</param>
        <param name="baud_rate">115200</param>
      </hardware>

      <joint name="left_wheel_joint">
        <command_interface name="velocity"/>
        <state_interface name="position"/>
        <state_interface name="velocity"/>
      </joint>

      <joint name="right_wheel_joint">
        <command_interface name="velocity"/>
        <state_interface name="position"/>
        <state_interface name="velocity"/>
      </joint>
    </ros2_control>

  </xacro:macro>

</robot>